<?xml version="1.0"?>
<robot name="robotarmv2meters">

  <!--
    Base link (cylinder), from z=0 to z=0.1
  -->
  <link name="base_link">
    <visual>
      <geometry>
        <cylinder length="0.1" radius="0.1"/>
      </geometry>
      <origin xyz="0 0 0.05" rpy="0 0 0"/>
      <material name="grey"/>
    </visual>
    <collision>
      <geometry>
        <cylinder length="0.1" radius="0.1"/>
      </geometry>
      <origin xyz="0 0 0.05" rpy="0 0 0"/>
    </collision>
    <inertial>
      <mass value="1.0"/>
      <origin xyz="0 0 0.05"/>
      <inertia ixx="0.01" ixy="0" ixz="0" iyy="0.01" iyz="0" izz="0.01"/>
    </inertial>
  </link>

  <joint name="base_motor_joint" type="revolute">
    <parent link="base_link"/>
    <child link="base_motor"/>
    <origin xyz="0 0 0.1" rpy="0 0 0"/>
    <!-- Rotate around Z-axis (allow the base to spin) -->
    <axis xyz="0 0 1"/>
    <limit lower="-3.14" upper="3.14" effort="10.0" velocity="1.0"/>
  </joint>

  <!--
    Base motor (box), from z=0.1 to z=0.2
  -->
  <link name="base_motor">
    <visual>
      <geometry>
        <box size="0.075 0.075 0.1"/>
      </geometry>
      <origin xyz="0 0 0.05" rpy="0 0 0"/>
      <material name="blue"/>
    </visual>
    <collision>
      <geometry>
        <box size="0.075 0.075 0.1"/>
      </geometry>
      <origin xyz="0 0 0.05" rpy="0 0 0"/>
    </collision>
    <inertial>
      <mass value="0.5"/>
      <origin xyz="0 0 0.05"/>
      <inertia ixx="0.005" ixy="0" ixz="0" iyy="0.005" iyz="0" izz="0.005"/>
    </inertial>
  </link>


  <!--
    Motor 1 (box, 0.05 m tall), from z=0.2 to z=0.25
    Rotates around X-axis
  -->
  <joint name="motor_1_joint" type="revolute">
    <parent link="base_motor"/>
    <child link="motor_1"/>
    <origin xyz="0 0 0.1" rpy="0 0 0"/>
    <axis xyz="1 0 0"/>
    <limit lower="-1.57" upper="1.57" effort="10.0" velocity="1.0"/>
  </joint>

  <link name="motor_1">
    <visual>
      <geometry>
        <box size="0.05 0.05 0.05"/>
      </geometry>
      <origin xyz="0 0 0.025" rpy="0 0 0"/>
      <material name="red"/>
    </visual>
    <collision>
      <geometry>
        <box size="0.05 0.05 0.05"/>
      </geometry>
      <origin xyz="0 0 0.025" rpy="0 0 0"/>
    </collision>
    <inertial>
      <mass value="0.2"/>
      <origin xyz="0 0 0.025"/>
      <inertia ixx="0.002" ixy="0" ixz="0" iyy="0.002" iyz="0" izz="0.002"/>
    </inertial>
  </link>


  <!--
    Arm 1 (0.25 m tall), from z=0.25 to z=0.5
    Fixed joint
  -->
  <joint name="arm_1_joint" type="fixed">
    <parent link="motor_1"/>
    <child link="arm_1"/>
    <!-- The motor_1 is 0.05 high, so the top is 0.05 above its origin -->
    <origin xyz="0 0 0.05" rpy="0 0 0"/>
  </joint>

  <link name="arm_1">
    <visual>
      <geometry>
        <!-- New length: 0.25 -->
        <box size="0.04 0.04 0.25"/>
      </geometry>
      <!-- Half of 0.25 is 0.125 -->
      <origin xyz="0 0 0.125" rpy="0 0 0"/>
      <material name="green"/>
    </visual>
    <collision>
      <geometry>
        <box size="0.04 0.04 0.25"/>
      </geometry>
      <origin xyz="0 0 0.125" rpy="0 0 0"/>
    </collision>
    <inertial>
      <mass value="0.3"/>
      <origin xyz="0 0 0.125"/>
      <inertia ixx="0.003" ixy="0" ixz="0" iyy="0.003" iyz="0" izz="0.003"/>
    </inertial>
  </link>


  <!--
    Motor 2 (0.05 m tall), from z=0.5 to z=0.55
    Rotates around X
  -->
  <joint name="motor_2_joint" type="revolute">
    <parent link="arm_1"/>
    <child link="motor_2"/>
    <!-- The top of arm_1 is 0.25 above its origin -->
    <origin xyz="0 0 0.25" rpy="0 0 0"/>
    <axis xyz="1 0 0"/>
    <limit lower="-1.57" upper="1.57" effort="10.0" velocity="1.0"/>
  </joint>

  <link name="motor_2">
    <visual>
      <geometry>
        <box size="0.05 0.05 0.05"/>
      </geometry>
      <origin xyz="0 0 0.025" rpy="0 0 0"/>
      <material name="red"/>
    </visual>
    <collision>
      <geometry>
        <box size="0.05 0.05 0.05"/>
      </geometry>
      <origin xyz="0 0 0.025" rpy="0 0 0"/>
    </collision>
    <inertial>
      <mass value="0.2"/>
      <origin xyz="0 0 0.025"/>
      <inertia ixx="0.002" ixy="0" ixz="0" iyy="0.002" iyz="0" izz="0.002"/>
    </inertial>
  </link>


  <!--
    Arm 2 (0.625 m tall), from z=0.55 to z=1.175
    Fixed
  -->
  <joint name="arm_2_joint" type="fixed">
    <parent link="motor_2"/>
    <child link="arm_2"/>
    <!-- motor_2 is 0.05 tall, so top is 0.05 above motor_2 origin -->
    <origin xyz="0 0 0.05" rpy="0 0 0"/>
  </joint>

  <link name="arm_2">
    <visual>
      <geometry>
        <!-- New length: 0.625 -->
        <box size="0.04 0.04 0.625"/>
      </geometry>
      <!-- Half of 0.625 is 0.3125 -->
      <origin xyz="0 0 0.3125" rpy="0 0 0"/>
      <material name="green"/>
    </visual>
    <collision>
      <geometry>
        <box size="0.04 0.04 0.625"/>
      </geometry>
      <origin xyz="0 0 0.3125" rpy="0 0 0"/>
    </collision>
    <inertial>
      <mass value="0.3"/>
      <origin xyz="0 0 0.3125"/>
      <inertia ixx="0.003" ixy="0" ixz="0" iyy="0.003" iyz="0" izz="0.003"/>
    </inertial>
  </link>


  <!--
    Motor 3 (0.05 m tall), from z=1.175 to z=1.225
    Rotates around X
  -->
  <joint name="motor_3_joint" type="revolute">
    <parent link="arm_2"/>
    <child link="motor_3"/>
    <!-- top of arm_2 is 0.625 above arm_2 origin -->
    <origin xyz="0 0 0.625" rpy="0 0 0"/>
    <axis xyz="1 0 0"/>
    <limit lower="-1.57" upper="1.57" effort="10.0" velocity="1.0"/>
  </joint>

  <link name="motor_3">
    <visual>
      <geometry>
        <box size="0.05 0.05 0.05"/>
      </geometry>
      <origin xyz="0 0 0.025" rpy="0 0 0"/>
      <material name="red"/>
    </visual>
    <collision>
      <geometry>
        <box size="0.05 0.05 0.05"/>
      </geometry>
      <origin xyz="0 0 0.025" rpy="0 0 0"/>
    </collision>
    <inertial>
      <mass value="0.2"/>
      <origin xyz="0 0 0.025"/>
      <inertia ixx="0.002" ixy="0" ixz="0" iyy="0.002" iyz="0" izz="0.002"/>
    </inertial>
  </link>


  <!--
    Arm 3 (0.625 m tall), from z=1.225 to z=1.85
    Fixed
  -->
  <joint name="arm_3_joint" type="fixed">
    <parent link="motor_3"/>
    <child link="arm_3"/>
    <origin xyz="0 0 0.05" rpy="0 0 0"/>
  </joint>

  <link name="arm_3">
    <visual>
      <geometry>
        <!-- New length: 0.625 -->
        <box size="0.04 0.04 0.625"/>
      </geometry>
      <!-- Half of 0.625 is 0.3125 -->
      <origin xyz="0 0 0.3125" rpy="0 0 0"/>
      <material name="green"/>
    </visual>
    <collision>
      <geometry>
        <box size="0.04 0.04 0.625"/>
      </geometry>
      <origin xyz="0 0 0.3125" rpy="0 0 0"/>
    </collision>
    <inertial>
      <mass value="0.3"/>
      <origin xyz="0 0 0.3125"/>
      <inertia ixx="0.003" ixy="0" ixz="0" iyy="0.003" iyz="0" izz="0.003"/>
    </inertial>
  </link>


  <!--
    Dummy End Link
    Forces IkPy to include arm_3 in the chain (not the last link).
    This link is a tiny sphere at the top of arm_3: z=1.85 total
  -->
  <joint name="dummy_end_joint" type="fixed">
    <parent link="arm_3"/>
    <child link="dummy_end"/>
    <!-- top of arm_3 is 0.625 above its origin -->
    <origin xyz="0 0 0.625" rpy="0 0 0"/>
  </joint>

  <link name="dummy_end">
    <visual>
      <geometry>
        <sphere radius="0.001"/>
      </geometry>
      <origin xyz="0 0 0" rpy="0 0 0"/>
      <material name="invisible"/>
    </visual>
    <collision>
      <geometry>
        <sphere radius="0.001"/>
      </geometry>
      <origin xyz="0 0 0" rpy="0 0 0"/>
    </collision>
    <inertial>
      <mass value="0.001"/>
      <origin xyz="0 0 0"/>
      <inertia ixx="1e-6" ixy="0" ixz="0" iyy="1e-6" iyz="0" izz="1e-6"/>
    </inertial>
  </link>

</robot>
